[2021-06-06 17:36:40,723] {taskinstance.py:851} INFO - Dependencies all met for <TaskInstance: forex_data_pipeline.spark 2021-06-05T00:00:00+00:00 [queued]>
[2021-06-06 17:36:40,797] {taskinstance.py:851} INFO - Dependencies all met for <TaskInstance: forex_data_pipeline.spark 2021-06-05T00:00:00+00:00 [queued]>
[2021-06-06 17:36:40,814] {taskinstance.py:1042} INFO - 
--------------------------------------------------------------------------------
[2021-06-06 17:36:40,817] {taskinstance.py:1043} INFO - Starting attempt 4 of 5
[2021-06-06 17:36:40,819] {taskinstance.py:1044} INFO - 
--------------------------------------------------------------------------------
[2021-06-06 17:36:40,842] {taskinstance.py:1063} INFO - Executing <Task(PythonOperator): spark> on 2021-06-05T00:00:00+00:00
[2021-06-06 17:36:40,853] {standard_task_runner.py:52} INFO - Started process 2639 to run task
[2021-06-06 17:36:40,879] {standard_task_runner.py:76} INFO - Running: ['airflow', 'tasks', 'run', 'forex_data_pipeline', 'spark', '2021-06-05T00:00:00+00:00', '--job-id', '52', '--pool', 'default_pool', '--raw', '--subdir', 'DAGS_FOLDER/dag_spark.py', '--cfg-path', '/tmp/tmpun8pbdal', '--error-file', '/tmp/tmplpge4a65']
[2021-06-06 17:36:40,889] {standard_task_runner.py:77} INFO - Job 52: Subtask spark
[2021-06-06 17:36:41,168] {logging_mixin.py:104} INFO - Running <TaskInstance: forex_data_pipeline.spark 2021-06-05T00:00:00+00:00 [running]> on host 72eec67484fb
[2021-06-06 17:36:41,341] {taskinstance.py:1257} INFO - Exporting the following env vars:
AIRFLOW_CTX_DAG_EMAIL=admin@localhost.com
AIRFLOW_CTX_DAG_OWNER=airflow
AIRFLOW_CTX_DAG_ID=forex_data_pipeline
AIRFLOW_CTX_TASK_ID=spark
AIRFLOW_CTX_EXECUTION_DATE=2021-06-05T00:00:00+00:00
AIRFLOW_CTX_DAG_RUN_ID=scheduled__2021-06-05T00:00:00+00:00
[2021-06-06 17:36:41,348] {logging_mixin.py:104} INFO - ÉNTRO AQUI!!!???¿
[2021-06-06 17:37:34,216] {logging_mixin.py:104} INFO - ESTOY AQUI¿¿
[2021-06-06 17:43:23,913] {local_task_job.py:188} WARNING - State of this instance has been externally set to failed. Terminating instance.
[2021-06-06 17:43:23,946] {process_utils.py:100} INFO - Sending Signals.SIGTERM to GPID 2639
[2021-06-06 17:43:23,962] {taskinstance.py:1239} ERROR - Received SIGTERM. Terminating subprocesses.
[2021-06-06 17:43:23,979] {java_gateway.py:1210} INFO - Error while receiving.
Traceback (most recent call last):
  File "/home/airflow/.local/lib/python3.7/site-packages/py4j/java_gateway.py", line 1200, in send_command
    answer = smart_decode(self.stream.readline()[:-1])
  File "/usr/local/lib/python3.7/socket.py", line 589, in readinto
    return self._sock.recv_into(b)
  File "/home/airflow/.local/lib/python3.7/site-packages/airflow/models/taskinstance.py", line 1241, in signal_handler
    raise AirflowException("Task received SIGTERM signal")
airflow.exceptions.AirflowException: Task received SIGTERM signal
[2021-06-06 17:43:24,178] {java_gateway.py:1051} ERROR - Exception while sending command.
Traceback (most recent call last):
  File "/home/airflow/.local/lib/python3.7/site-packages/py4j/java_gateway.py", line 1200, in send_command
    answer = smart_decode(self.stream.readline()[:-1])
  File "/usr/local/lib/python3.7/socket.py", line 589, in readinto
    return self._sock.recv_into(b)
  File "/home/airflow/.local/lib/python3.7/site-packages/airflow/models/taskinstance.py", line 1241, in signal_handler
    raise AirflowException("Task received SIGTERM signal")
airflow.exceptions.AirflowException: Task received SIGTERM signal

During handling of the above exception, another exception occurred:

Traceback (most recent call last):
  File "/home/airflow/.local/lib/python3.7/site-packages/py4j/java_gateway.py", line 1033, in send_command
    response = connection.send_command(command)
  File "/home/airflow/.local/lib/python3.7/site-packages/py4j/java_gateway.py", line 1212, in send_command
    "Error while receiving", e, proto.ERROR_ON_RECEIVE)
py4j.protocol.Py4JNetworkError: Error while receiving
[2021-06-06 17:43:24,193] {taskinstance.py:1455} ERROR - An error occurred while calling o59.csv
Traceback (most recent call last):
  File "/home/airflow/.local/lib/python3.7/site-packages/airflow/models/taskinstance.py", line 1112, in _run_raw_task
    self._prepare_and_execute_task_with_callbacks(context, task)
  File "/home/airflow/.local/lib/python3.7/site-packages/airflow/models/taskinstance.py", line 1285, in _prepare_and_execute_task_with_callbacks
    result = self._execute_task(context, task_copy)
  File "/home/airflow/.local/lib/python3.7/site-packages/airflow/models/taskinstance.py", line 1315, in _execute_task
    result = task_copy.execute(context=context)
  File "/home/airflow/.local/lib/python3.7/site-packages/airflow/operators/python.py", line 117, in execute
    return_value = self.execute_callable()
  File "/home/airflow/.local/lib/python3.7/site-packages/airflow/operators/python.py", line 128, in execute_callable
    return self.python_callable(*self.op_args, **self.op_kwargs)
  File "/opt/airflow/dags/test.py", line 26, in execute_spark
    path="dags/data/uk-macroeconomic-data.csv", sep=",", header=True
  File "/home/airflow/.local/lib/python3.7/site-packages/pyspark/sql/readwriter.py", line 737, in csv
    return self._df(self._jreader.csv(self._spark._sc._jvm.PythonUtils.toSeq(path)))
  File "/home/airflow/.local/lib/python3.7/site-packages/py4j/java_gateway.py", line 1305, in __call__
    answer, self.gateway_client, self.target_id, self.name)
  File "/home/airflow/.local/lib/python3.7/site-packages/pyspark/sql/utils.py", line 111, in deco
    return f(*a, **kw)
  File "/home/airflow/.local/lib/python3.7/site-packages/py4j/protocol.py", line 336, in get_return_value
    format(target_id, ".", name))
py4j.protocol.Py4JError: An error occurred while calling o59.csv
[2021-06-06 17:43:24,316] {taskinstance.py:1503} INFO - Marking task as UP_FOR_RETRY. dag_id=forex_data_pipeline, task_id=spark, execution_date=20210605T000000, start_date=20210606T173640, end_date=20210606T174324
[2021-06-06 17:43:24,658] {process_utils.py:66} INFO - Process psutil.Process(pid=2639, status='terminated', exitcode=1, started='17:36:40') (2639) terminated with exit code 1
[2021-06-06 17:43:29,400] {process_utils.py:66} INFO - Process psutil.Process(pid=2640, status='terminated', started='17:36:41') (2640) terminated with exit code None
