[2021-06-06 22:28:33,678] {taskinstance.py:851} INFO - Dependencies all met for <TaskInstance: forex_data_pipeline.test2 2021-06-05T00:00:00+00:00 [queued]>
[2021-06-06 22:28:33,913] {taskinstance.py:851} INFO - Dependencies all met for <TaskInstance: forex_data_pipeline.test2 2021-06-05T00:00:00+00:00 [queued]>
[2021-06-06 22:28:33,919] {taskinstance.py:1042} INFO - 
--------------------------------------------------------------------------------
[2021-06-06 22:28:33,934] {taskinstance.py:1043} INFO - Starting attempt 5 of 6
[2021-06-06 22:28:33,937] {taskinstance.py:1044} INFO - 
--------------------------------------------------------------------------------
[2021-06-06 22:28:34,004] {taskinstance.py:1063} INFO - Executing <Task(PythonOperator): test2> on 2021-06-05T00:00:00+00:00
[2021-06-06 22:28:34,020] {standard_task_runner.py:52} INFO - Started process 4927 to run task
[2021-06-06 22:28:34,040] {standard_task_runner.py:76} INFO - Running: ['airflow', 'tasks', 'run', 'forex_data_pipeline', 'test2', '2021-06-05T00:00:00+00:00', '--job-id', '63', '--pool', 'default_pool', '--raw', '--subdir', 'DAGS_FOLDER/dag_spark.py', '--cfg-path', '/tmp/tmp28i466rm', '--error-file', '/tmp/tmpk7lpz50c']
[2021-06-06 22:28:34,050] {standard_task_runner.py:77} INFO - Job 63: Subtask test2
[2021-06-06 22:28:34,246] {logging_mixin.py:104} INFO - Running <TaskInstance: forex_data_pipeline.test2 2021-06-05T00:00:00+00:00 [running]> on host 72eec67484fb
[2021-06-06 22:28:34,549] {taskinstance.py:1257} INFO - Exporting the following env vars:
AIRFLOW_CTX_DAG_EMAIL=admin@localhost.com
AIRFLOW_CTX_DAG_OWNER=airflow
AIRFLOW_CTX_DAG_ID=forex_data_pipeline
AIRFLOW_CTX_TASK_ID=test2
AIRFLOW_CTX_EXECUTION_DATE=2021-06-05T00:00:00+00:00
AIRFLOW_CTX_DAG_RUN_ID=scheduled__2021-06-05T00:00:00+00:00
[2021-06-06 22:34:53,294] {local_task_job.py:188} WARNING - State of this instance has been externally set to failed. Terminating instance.
[2021-06-06 22:34:53,405] {process_utils.py:100} INFO - Sending Signals.SIGTERM to GPID 4927
[2021-06-06 22:34:53,458] {taskinstance.py:1239} ERROR - Received SIGTERM. Terminating subprocesses.
[2021-06-06 22:34:53,516] {java_gateway.py:1210} INFO - Error while receiving.
Traceback (most recent call last):
  File "/home/airflow/.local/lib/python3.7/site-packages/py4j/java_gateway.py", line 1200, in send_command
    answer = smart_decode(self.stream.readline()[:-1])
  File "/usr/local/lib/python3.7/socket.py", line 589, in readinto
    return self._sock.recv_into(b)
  File "/home/airflow/.local/lib/python3.7/site-packages/airflow/models/taskinstance.py", line 1241, in signal_handler
    raise AirflowException("Task received SIGTERM signal")
airflow.exceptions.AirflowException: Task received SIGTERM signal
[2021-06-06 22:34:53,624] {java_gateway.py:1051} ERROR - Exception while sending command.
Traceback (most recent call last):
  File "/home/airflow/.local/lib/python3.7/site-packages/py4j/java_gateway.py", line 1200, in send_command
    answer = smart_decode(self.stream.readline()[:-1])
  File "/usr/local/lib/python3.7/socket.py", line 589, in readinto
    return self._sock.recv_into(b)
  File "/home/airflow/.local/lib/python3.7/site-packages/airflow/models/taskinstance.py", line 1241, in signal_handler
    raise AirflowException("Task received SIGTERM signal")
airflow.exceptions.AirflowException: Task received SIGTERM signal

During handling of the above exception, another exception occurred:

Traceback (most recent call last):
  File "/home/airflow/.local/lib/python3.7/site-packages/py4j/java_gateway.py", line 1033, in send_command
    response = connection.send_command(command)
  File "/home/airflow/.local/lib/python3.7/site-packages/py4j/java_gateway.py", line 1212, in send_command
    "Error while receiving", e, proto.ERROR_ON_RECEIVE)
py4j.protocol.Py4JNetworkError: Error while receiving
[2021-06-06 22:34:53,749] {taskinstance.py:1455} ERROR - An error occurred while calling o42.showString
Traceback (most recent call last):
  File "/home/airflow/.local/lib/python3.7/site-packages/airflow/models/taskinstance.py", line 1112, in _run_raw_task
    self._prepare_and_execute_task_with_callbacks(context, task)
  File "/home/airflow/.local/lib/python3.7/site-packages/airflow/models/taskinstance.py", line 1285, in _prepare_and_execute_task_with_callbacks
    result = self._execute_task(context, task_copy)
  File "/home/airflow/.local/lib/python3.7/site-packages/airflow/models/taskinstance.py", line 1315, in _execute_task
    result = task_copy.execute(context=context)
  File "/home/airflow/.local/lib/python3.7/site-packages/airflow/operators/python.py", line 117, in execute
    return_value = self.execute_callable()
  File "/home/airflow/.local/lib/python3.7/site-packages/airflow/operators/python.py", line 128, in execute_callable
    return self.python_callable(*self.op_args, **self.op_kwargs)
  File "/opt/airflow/dags/spark_test.py", line 27, in test_spark
  File "/home/airflow/.local/lib/python3.7/site-packages/pyspark/sql/dataframe.py", line 440, in show
    print(self._jdf.showString(n, 20, vertical))
  File "/home/airflow/.local/lib/python3.7/site-packages/py4j/java_gateway.py", line 1305, in __call__
    answer, self.gateway_client, self.target_id, self.name)
  File "/home/airflow/.local/lib/python3.7/site-packages/pyspark/sql/utils.py", line 131, in deco
    return f(*a, **kw)
  File "/home/airflow/.local/lib/python3.7/site-packages/py4j/protocol.py", line 336, in get_return_value
    format(target_id, ".", name))
py4j.protocol.Py4JError: An error occurred while calling o42.showString
[2021-06-06 22:34:54,161] {taskinstance.py:1503} INFO - Marking task as UP_FOR_RETRY. dag_id=forex_data_pipeline, task_id=test2, execution_date=20210605T000000, start_date=20210606T222833, end_date=20210606T223453
[2021-06-06 22:34:59,309] {process_utils.py:66} INFO - Process psutil.Process(pid=4927, status='terminated', exitcode=1, started='22:28:33') (4927) terminated with exit code 1
[2021-06-06 22:35:11,094] {process_utils.py:66} INFO - Process psutil.Process(pid=4928, status='terminated', started='22:28:34') (4928) terminated with exit code None
